{
  "cells": [
    {
      "cell_type": "code",
      "execution_count": null,
      "metadata": {
        "id": "3KLvSlquRb-7"
      },
      "outputs": [],
      "source": [
        "from drive.MyDrive.DL.codes.hatespeech.pipelines import ML\n",
        "import warnings\n",
        "warnings.filterwarnings('ignore')\n",
        "\n",
        "labels_1 = ['train','test','val']\n",
        "labels_2 = ['0','1','2','3','4','5']\n",
        "\n",
        "\n",
        "for l1 in labels_1:\n",
        "  for l2 in labels_2:\n",
        "    with open(f'/content/drive/MyDrive/DL/PREG1/hate-speech/txt/{l1}/{l2}.txt','r') as f:\n",
        "      st = f.readlines()\n",
        "\n",
        "    for i, line in enumerate(st):\n",
        "      with open(f'/content/drive/MyDrive/DL/PREG1/hate-speech/txt/{l1}/{l2}/{i}.txt','w') as f:\n",
        "        f.write(line[:-1])"
      ]
    },
    {
      "cell_type": "code",
      "execution_count": null,
      "metadata": {
        "colab": {
          "base_uri": "https://localhost:8080/"
        },
        "id": "jWw9bLUmSsIz",
        "outputId": "96ca2a74-7e3d-474c-890d-02ea507c3703"
      },
      "outputs": [
        {
          "name": "stdout",
          "output_type": "stream",
          "text": [
            "Mounted at /content/drive\n"
          ]
        }
      ],
      "source": [
        "from google.colab import drive\n",
        "drive.mount('/content/drive')"
      ]
    },
    {
      "cell_type": "code",
      "execution_count": null,
      "metadata": {
        "id": "T-Kb57n28stm"
      },
      "outputs": [],
      "source": []
    },
    {
      "cell_type": "code",
      "execution_count": null,
      "metadata": {
        "colab": {
          "background_save": true,
          "base_uri": "https://localhost:8080/"
        },
        "id": "uMwSmfWXRb-8",
        "outputId": "9038e75c-cad0-4a60-8962-4a306c634fc2"
      },
      "outputs": [
        {
          "name": "stdout",
          "output_type": "stream",
          "text": [
            "Found 78886 files belonging to 6 classes.\n",
            "Found 5000 files belonging to 6 classes.\n",
            "Found 10000 files belonging to 6 classes.\n",
            "Training ['tf', 'knn']\n",
            "{'tf__max_features': [500, 1000, 5000, 10000], 'tf__max_df': [0.75, 0.85, 1.0], 'tf__use_idf': [True, False], 'knn__n_neighbors': [3, 5, 10, 15, 20]}\n",
            "Fitting 3 folds for each of 50 candidates, totalling 150 fits\n",
            "Training ['tf', 'rf']\n",
            "{'tf__max_features': [500, 1000, 5000, 10000], 'tf__max_df': [0.75, 0.85, 1.0], 'tf__use_idf': [True, False], 'rf__n_estimators': [50, 100, 200, 500], 'rf__criterion': ['gini', 'entropy'], 'rf__max_depth': ['None', 10, 20, 30, 50, 100], 'rf__min_samples_split': [2, 5, 10], 'rf__min_samples_leaf': [1, 2, 5, 10], 'rf__max_features': ['auto', 'sqrt', 'log2']}\n",
            "Fitting 3 folds for each of 50 candidates, totalling 150 fits\n",
            "Training ['w2v', 'knn']\n",
            "{'w2v__vector_size': [50, 100, 200, 300], 'w2v__window': [3, 5, 7], 'w2v__min_count': [1, 5, 10], 'w2v__sg': [0, 1], 'knn__n_neighbors': [3, 5, 10, 15, 20]}\n",
            "Fitting 3 folds for each of 50 candidates, totalling 150 fits\n"
          ]
        },
        {
          "ename": "ValueError",
          "evalue": "\nAll the 150 fits failed.\nIt is very likely that your model is misconfigured.\nYou can try to debug the error by setting error_score='raise'.\n\nBelow are more details about the failures:\n--------------------------------------------------------------------------------\n19 fits failed with the following error:\nTraceback (most recent call last):\n  File \"/usr/local/lib/python3.10/dist-packages/sklearn/model_selection/_validation.py\", line 888, in _fit_and_score\n    estimator.fit(X_train, y_train, **fit_params)\n  File \"/usr/local/lib/python3.10/dist-packages/sklearn/base.py\", line 1473, in wrapper\n    return fit_method(estimator, *args, **kwargs)\n  File \"/usr/local/lib/python3.10/dist-packages/sklearn/pipeline.py\", line 469, in fit\n    Xt = self._fit(X, y, routed_params)\n  File \"/usr/local/lib/python3.10/dist-packages/sklearn/pipeline.py\", line 406, in _fit\n    X, fitted_transformer = fit_transform_one_cached(\n  File \"/usr/local/lib/python3.10/dist-packages/joblib/memory.py\", line 312, in __call__\n    return self.func(*args, **kwargs)\n  File \"/usr/local/lib/python3.10/dist-packages/sklearn/pipeline.py\", line 1310, in _fit_transform_one\n    res = transformer.fit_transform(X, y, **params.get(\"fit_transform\", {}))\n  File \"/usr/local/lib/python3.10/dist-packages/sklearn/utils/_set_output.py\", line 316, in wrapped\n    data_to_wrap = f(self, X, *args, **kwargs)\n  File \"/usr/local/lib/python3.10/dist-packages/sklearn/base.py\", line 1101, in fit_transform\n    return self.fit(X, y, **fit_params).transform(X)\n  File \"/usr/local/lib/python3.10/dist-packages/sklearn/utils/_set_output.py\", line 316, in wrapped\n    data_to_wrap = f(self, X, *args, **kwargs)\n  File \"/content/drive/MyDrive/DL/codes/hatespeech/pipelines.py\", line 93, in transform\n    feature_vectors.append(np.mean(vectors, axis=0))\n  File \"/usr/local/lib/python3.10/dist-packages/numpy/core/fromnumeric.py\", line 3504, in mean\n    return _methods._mean(a, axis=axis, dtype=dtype,\n  File \"/usr/local/lib/python3.10/dist-packages/numpy/core/_methods.py\", line 102, in _mean\n    arr = asanyarray(a)\nValueError: setting an array element with a sequence. The requested array has an inhomogeneous shape after 1 dimensions. The detected shape was (9,) + inhomogeneous part.\n\n--------------------------------------------------------------------------------\n38 fits failed with the following error:\nTraceback (most recent call last):\n  File \"/usr/local/lib/python3.10/dist-packages/sklearn/model_selection/_validation.py\", line 888, in _fit_and_score\n    estimator.fit(X_train, y_train, **fit_params)\n  File \"/usr/local/lib/python3.10/dist-packages/sklearn/base.py\", line 1473, in wrapper\n    return fit_method(estimator, *args, **kwargs)\n  File \"/usr/local/lib/python3.10/dist-packages/sklearn/pipeline.py\", line 469, in fit\n    Xt = self._fit(X, y, routed_params)\n  File \"/usr/local/lib/python3.10/dist-packages/sklearn/pipeline.py\", line 406, in _fit\n    X, fitted_transformer = fit_transform_one_cached(\n  File \"/usr/local/lib/python3.10/dist-packages/joblib/memory.py\", line 312, in __call__\n    return self.func(*args, **kwargs)\n  File \"/usr/local/lib/python3.10/dist-packages/sklearn/pipeline.py\", line 1310, in _fit_transform_one\n    res = transformer.fit_transform(X, y, **params.get(\"fit_transform\", {}))\n  File \"/usr/local/lib/python3.10/dist-packages/sklearn/utils/_set_output.py\", line 316, in wrapped\n    data_to_wrap = f(self, X, *args, **kwargs)\n  File \"/usr/local/lib/python3.10/dist-packages/sklearn/base.py\", line 1101, in fit_transform\n    return self.fit(X, y, **fit_params).transform(X)\n  File \"/usr/local/lib/python3.10/dist-packages/sklearn/utils/_set_output.py\", line 316, in wrapped\n    data_to_wrap = f(self, X, *args, **kwargs)\n  File \"/content/drive/MyDrive/DL/codes/hatespeech/pipelines.py\", line 93, in transform\n    feature_vectors.append(np.mean(vectors, axis=0))\n  File \"/usr/local/lib/python3.10/dist-packages/numpy/core/fromnumeric.py\", line 3504, in mean\n    return _methods._mean(a, axis=axis, dtype=dtype,\n  File \"/usr/local/lib/python3.10/dist-packages/numpy/core/_methods.py\", line 102, in _mean\n    arr = asanyarray(a)\nValueError: setting an array element with a sequence. The requested array has an inhomogeneous shape after 1 dimensions. The detected shape was (13,) + inhomogeneous part.\n\n--------------------------------------------------------------------------------\n13 fits failed with the following error:\nTraceback (most recent call last):\n  File \"/usr/local/lib/python3.10/dist-packages/sklearn/model_selection/_validation.py\", line 888, in _fit_and_score\n    estimator.fit(X_train, y_train, **fit_params)\n  File \"/usr/local/lib/python3.10/dist-packages/sklearn/base.py\", line 1473, in wrapper\n    return fit_method(estimator, *args, **kwargs)\n  File \"/usr/local/lib/python3.10/dist-packages/sklearn/pipeline.py\", line 469, in fit\n    Xt = self._fit(X, y, routed_params)\n  File \"/usr/local/lib/python3.10/dist-packages/sklearn/pipeline.py\", line 406, in _fit\n    X, fitted_transformer = fit_transform_one_cached(\n  File \"/usr/local/lib/python3.10/dist-packages/joblib/memory.py\", line 312, in __call__\n    return self.func(*args, **kwargs)\n  File \"/usr/local/lib/python3.10/dist-packages/sklearn/pipeline.py\", line 1310, in _fit_transform_one\n    res = transformer.fit_transform(X, y, **params.get(\"fit_transform\", {}))\n  File \"/usr/local/lib/python3.10/dist-packages/sklearn/utils/_set_output.py\", line 316, in wrapped\n    data_to_wrap = f(self, X, *args, **kwargs)\n  File \"/usr/local/lib/python3.10/dist-packages/sklearn/base.py\", line 1101, in fit_transform\n    return self.fit(X, y, **fit_params).transform(X)\n  File \"/usr/local/lib/python3.10/dist-packages/sklearn/utils/_set_output.py\", line 316, in wrapped\n    data_to_wrap = f(self, X, *args, **kwargs)\n  File \"/content/drive/MyDrive/DL/codes/hatespeech/pipelines.py\", line 93, in transform\n    feature_vectors.append(np.mean(vectors, axis=0))\n  File \"/usr/local/lib/python3.10/dist-packages/numpy/core/fromnumeric.py\", line 3504, in mean\n    return _methods._mean(a, axis=axis, dtype=dtype,\n  File \"/usr/local/lib/python3.10/dist-packages/numpy/core/_methods.py\", line 102, in _mean\n    arr = asanyarray(a)\nValueError: setting an array element with a sequence. The requested array has an inhomogeneous shape after 1 dimensions. The detected shape was (8,) + inhomogeneous part.\n\n--------------------------------------------------------------------------------\n62 fits failed with the following error:\nTraceback (most recent call last):\n  File \"/usr/local/lib/python3.10/dist-packages/sklearn/model_selection/_validation.py\", line 888, in _fit_and_score\n    estimator.fit(X_train, y_train, **fit_params)\n  File \"/usr/local/lib/python3.10/dist-packages/sklearn/base.py\", line 1473, in wrapper\n    return fit_method(estimator, *args, **kwargs)\n  File \"/usr/local/lib/python3.10/dist-packages/sklearn/pipeline.py\", line 469, in fit\n    Xt = self._fit(X, y, routed_params)\n  File \"/usr/local/lib/python3.10/dist-packages/sklearn/pipeline.py\", line 406, in _fit\n    X, fitted_transformer = fit_transform_one_cached(\n  File \"/usr/local/lib/python3.10/dist-packages/joblib/memory.py\", line 312, in __call__\n    return self.func(*args, **kwargs)\n  File \"/usr/local/lib/python3.10/dist-packages/sklearn/pipeline.py\", line 1310, in _fit_transform_one\n    res = transformer.fit_transform(X, y, **params.get(\"fit_transform\", {}))\n  File \"/usr/local/lib/python3.10/dist-packages/sklearn/utils/_set_output.py\", line 316, in wrapped\n    data_to_wrap = f(self, X, *args, **kwargs)\n  File \"/usr/local/lib/python3.10/dist-packages/sklearn/base.py\", line 1101, in fit_transform\n    return self.fit(X, y, **fit_params).transform(X)\n  File \"/usr/local/lib/python3.10/dist-packages/sklearn/utils/_set_output.py\", line 316, in wrapped\n    data_to_wrap = f(self, X, *args, **kwargs)\n  File \"/content/drive/MyDrive/DL/codes/hatespeech/pipelines.py\", line 93, in transform\n    feature_vectors.append(np.mean(vectors, axis=0))\n  File \"/usr/local/lib/python3.10/dist-packages/numpy/core/fromnumeric.py\", line 3504, in mean\n    return _methods._mean(a, axis=axis, dtype=dtype,\n  File \"/usr/local/lib/python3.10/dist-packages/numpy/core/_methods.py\", line 102, in _mean\n    arr = asanyarray(a)\nValueError: setting an array element with a sequence. The requested array has an inhomogeneous shape after 1 dimensions. The detected shape was (12,) + inhomogeneous part.\n\n--------------------------------------------------------------------------------\n18 fits failed with the following error:\nTraceback (most recent call last):\n  File \"/usr/local/lib/python3.10/dist-packages/sklearn/model_selection/_validation.py\", line 888, in _fit_and_score\n    estimator.fit(X_train, y_train, **fit_params)\n  File \"/usr/local/lib/python3.10/dist-packages/sklearn/base.py\", line 1473, in wrapper\n    return fit_method(estimator, *args, **kwargs)\n  File \"/usr/local/lib/python3.10/dist-packages/sklearn/pipeline.py\", line 469, in fit\n    Xt = self._fit(X, y, routed_params)\n  File \"/usr/local/lib/python3.10/dist-packages/sklearn/pipeline.py\", line 406, in _fit\n    X, fitted_transformer = fit_transform_one_cached(\n  File \"/usr/local/lib/python3.10/dist-packages/joblib/memory.py\", line 312, in __call__\n    return self.func(*args, **kwargs)\n  File \"/usr/local/lib/python3.10/dist-packages/sklearn/pipeline.py\", line 1310, in _fit_transform_one\n    res = transformer.fit_transform(X, y, **params.get(\"fit_transform\", {}))\n  File \"/usr/local/lib/python3.10/dist-packages/sklearn/utils/_set_output.py\", line 316, in wrapped\n    data_to_wrap = f(self, X, *args, **kwargs)\n  File \"/usr/local/lib/python3.10/dist-packages/sklearn/base.py\", line 1101, in fit_transform\n    return self.fit(X, y, **fit_params).transform(X)\n  File \"/usr/local/lib/python3.10/dist-packages/sklearn/utils/_set_output.py\", line 316, in wrapped\n    data_to_wrap = f(self, X, *args, **kwargs)\n  File \"/content/drive/MyDrive/DL/codes/hatespeech/pipelines.py\", line 93, in transform\n    feature_vectors.append(np.mean(vectors, axis=0))\n  File \"/usr/local/lib/python3.10/dist-packages/numpy/core/fromnumeric.py\", line 3504, in mean\n    return _methods._mean(a, axis=axis, dtype=dtype,\n  File \"/usr/local/lib/python3.10/dist-packages/numpy/core/_methods.py\", line 102, in _mean\n    arr = asanyarray(a)\nValueError: setting an array element with a sequence. The requested array has an inhomogeneous shape after 1 dimensions. The detected shape was (7,) + inhomogeneous part.\n",
          "output_type": "error",
          "traceback": [
            "\u001b[0;31m---------------------------------------------------------------------------\u001b[0m",
            "\u001b[0;31mValueError\u001b[0m                                Traceback (most recent call last)",
            "\u001b[0;32m<ipython-input-5-79d5ab081608>\u001b[0m in \u001b[0;36m<cell line: 2>\u001b[0;34m()\u001b[0m\n\u001b[1;32m      1\u001b[0m \u001b[0mml\u001b[0m \u001b[0;34m=\u001b[0m \u001b[0mML\u001b[0m\u001b[0;34m(\u001b[0m\u001b[0;34m'txt'\u001b[0m\u001b[0;34m,\u001b[0m\u001b[0myaml_path\u001b[0m\u001b[0;34m=\u001b[0m\u001b[0;34m'/content/drive/MyDrive/DL/PREG1/config.yaml'\u001b[0m\u001b[0;34m)\u001b[0m\u001b[0;34m\u001b[0m\u001b[0;34m\u001b[0m\u001b[0m\n\u001b[0;32m----> 2\u001b[0;31m \u001b[0mml\u001b[0m\u001b[0;34m.\u001b[0m\u001b[0mtraining\u001b[0m\u001b[0;34m(\u001b[0m\u001b[0;34m)\u001b[0m\u001b[0;34m\u001b[0m\u001b[0;34m\u001b[0m\u001b[0m\n\u001b[0m\u001b[1;32m      3\u001b[0m \u001b[0mml\u001b[0m\u001b[0;34m.\u001b[0m\u001b[0mtest_accuracies\u001b[0m\u001b[0;34m(\u001b[0m\u001b[0;34m)\u001b[0m\u001b[0;34m\u001b[0m\u001b[0;34m\u001b[0m\u001b[0m\n",
            "\u001b[0;32m/content/drive/MyDrive/DL/codes/hatespeech/pipelines.py\u001b[0m in \u001b[0;36mtraining\u001b[0;34m(self, log_path)\u001b[0m\n\u001b[1;32m    190\u001b[0m                 \u001b[0mrandom_state\u001b[0m\u001b[0;34m=\u001b[0m\u001b[0;36m42\u001b[0m\u001b[0;34m\u001b[0m\u001b[0;34m\u001b[0m\u001b[0m\n\u001b[1;32m    191\u001b[0m             )\n\u001b[0;32m--> 192\u001b[0;31m             \u001b[0mrs\u001b[0m\u001b[0;34m.\u001b[0m\u001b[0mfit\u001b[0m\u001b[0;34m(\u001b[0m\u001b[0mx_train\u001b[0m\u001b[0;34m,\u001b[0m\u001b[0my_train\u001b[0m\u001b[0;34m)\u001b[0m\u001b[0;34m\u001b[0m\u001b[0;34m\u001b[0m\u001b[0m\n\u001b[0m\u001b[1;32m    193\u001b[0m             \u001b[0mself\u001b[0m\u001b[0;34m.\u001b[0m\u001b[0mbest_models\u001b[0m\u001b[0;34m.\u001b[0m\u001b[0mappend\u001b[0m\u001b[0;34m(\u001b[0m\u001b[0mrs\u001b[0m\u001b[0;34m.\u001b[0m\u001b[0mbest_estimator_\u001b[0m\u001b[0;34m)\u001b[0m\u001b[0;34m\u001b[0m\u001b[0;34m\u001b[0m\u001b[0m\n\u001b[1;32m    194\u001b[0m \u001b[0;34m\u001b[0m\u001b[0m\n",
            "\u001b[0;32m/usr/local/lib/python3.10/dist-packages/sklearn/base.py\u001b[0m in \u001b[0;36mwrapper\u001b[0;34m(estimator, *args, **kwargs)\u001b[0m\n\u001b[1;32m   1471\u001b[0m                 )\n\u001b[1;32m   1472\u001b[0m             ):\n\u001b[0;32m-> 1473\u001b[0;31m                 \u001b[0;32mreturn\u001b[0m \u001b[0mfit_method\u001b[0m\u001b[0;34m(\u001b[0m\u001b[0mestimator\u001b[0m\u001b[0;34m,\u001b[0m \u001b[0;34m*\u001b[0m\u001b[0margs\u001b[0m\u001b[0;34m,\u001b[0m \u001b[0;34m**\u001b[0m\u001b[0mkwargs\u001b[0m\u001b[0;34m)\u001b[0m\u001b[0;34m\u001b[0m\u001b[0;34m\u001b[0m\u001b[0m\n\u001b[0m\u001b[1;32m   1474\u001b[0m \u001b[0;34m\u001b[0m\u001b[0m\n\u001b[1;32m   1475\u001b[0m         \u001b[0;32mreturn\u001b[0m \u001b[0mwrapper\u001b[0m\u001b[0;34m\u001b[0m\u001b[0;34m\u001b[0m\u001b[0m\n",
            "\u001b[0;32m/usr/local/lib/python3.10/dist-packages/sklearn/model_selection/_search.py\u001b[0m in \u001b[0;36mfit\u001b[0;34m(self, X, y, **params)\u001b[0m\n\u001b[1;32m   1017\u001b[0m                 \u001b[0;32mreturn\u001b[0m \u001b[0mresults\u001b[0m\u001b[0;34m\u001b[0m\u001b[0;34m\u001b[0m\u001b[0m\n\u001b[1;32m   1018\u001b[0m \u001b[0;34m\u001b[0m\u001b[0m\n\u001b[0;32m-> 1019\u001b[0;31m             \u001b[0mself\u001b[0m\u001b[0;34m.\u001b[0m\u001b[0m_run_search\u001b[0m\u001b[0;34m(\u001b[0m\u001b[0mevaluate_candidates\u001b[0m\u001b[0;34m)\u001b[0m\u001b[0;34m\u001b[0m\u001b[0;34m\u001b[0m\u001b[0m\n\u001b[0m\u001b[1;32m   1020\u001b[0m \u001b[0;34m\u001b[0m\u001b[0m\n\u001b[1;32m   1021\u001b[0m             \u001b[0;31m# multimetric is determined here because in the case of a callable\u001b[0m\u001b[0;34m\u001b[0m\u001b[0;34m\u001b[0m\u001b[0m\n",
            "\u001b[0;32m/usr/local/lib/python3.10/dist-packages/sklearn/model_selection/_search.py\u001b[0m in \u001b[0;36m_run_search\u001b[0;34m(self, evaluate_candidates)\u001b[0m\n\u001b[1;32m   1958\u001b[0m     \u001b[0;32mdef\u001b[0m \u001b[0m_run_search\u001b[0m\u001b[0;34m(\u001b[0m\u001b[0mself\u001b[0m\u001b[0;34m,\u001b[0m \u001b[0mevaluate_candidates\u001b[0m\u001b[0;34m)\u001b[0m\u001b[0;34m:\u001b[0m\u001b[0;34m\u001b[0m\u001b[0;34m\u001b[0m\u001b[0m\n\u001b[1;32m   1959\u001b[0m         \u001b[0;34m\"\"\"Search n_iter candidates from param_distributions\"\"\"\u001b[0m\u001b[0;34m\u001b[0m\u001b[0;34m\u001b[0m\u001b[0m\n\u001b[0;32m-> 1960\u001b[0;31m         evaluate_candidates(\n\u001b[0m\u001b[1;32m   1961\u001b[0m             ParameterSampler(\n\u001b[1;32m   1962\u001b[0m                 \u001b[0mself\u001b[0m\u001b[0;34m.\u001b[0m\u001b[0mparam_distributions\u001b[0m\u001b[0;34m,\u001b[0m \u001b[0mself\u001b[0m\u001b[0;34m.\u001b[0m\u001b[0mn_iter\u001b[0m\u001b[0;34m,\u001b[0m \u001b[0mrandom_state\u001b[0m\u001b[0;34m=\u001b[0m\u001b[0mself\u001b[0m\u001b[0;34m.\u001b[0m\u001b[0mrandom_state\u001b[0m\u001b[0;34m\u001b[0m\u001b[0;34m\u001b[0m\u001b[0m\n",
            "\u001b[0;32m/usr/local/lib/python3.10/dist-packages/sklearn/model_selection/_search.py\u001b[0m in \u001b[0;36mevaluate_candidates\u001b[0;34m(candidate_params, cv, more_results)\u001b[0m\n\u001b[1;32m    994\u001b[0m                     )\n\u001b[1;32m    995\u001b[0m \u001b[0;34m\u001b[0m\u001b[0m\n\u001b[0;32m--> 996\u001b[0;31m                 \u001b[0m_warn_or_raise_about_fit_failures\u001b[0m\u001b[0;34m(\u001b[0m\u001b[0mout\u001b[0m\u001b[0;34m,\u001b[0m \u001b[0mself\u001b[0m\u001b[0;34m.\u001b[0m\u001b[0merror_score\u001b[0m\u001b[0;34m)\u001b[0m\u001b[0;34m\u001b[0m\u001b[0;34m\u001b[0m\u001b[0m\n\u001b[0m\u001b[1;32m    997\u001b[0m \u001b[0;34m\u001b[0m\u001b[0m\n\u001b[1;32m    998\u001b[0m                 \u001b[0;31m# For callable self.scoring, the return type is only know after\u001b[0m\u001b[0;34m\u001b[0m\u001b[0;34m\u001b[0m\u001b[0m\n",
            "\u001b[0;32m/usr/local/lib/python3.10/dist-packages/sklearn/model_selection/_validation.py\u001b[0m in \u001b[0;36m_warn_or_raise_about_fit_failures\u001b[0;34m(results, error_score)\u001b[0m\n\u001b[1;32m    527\u001b[0m                 \u001b[0;34mf\"Below are more details about the failures:\\n{fit_errors_summary}\"\u001b[0m\u001b[0;34m\u001b[0m\u001b[0;34m\u001b[0m\u001b[0m\n\u001b[1;32m    528\u001b[0m             )\n\u001b[0;32m--> 529\u001b[0;31m             \u001b[0;32mraise\u001b[0m \u001b[0mValueError\u001b[0m\u001b[0;34m(\u001b[0m\u001b[0mall_fits_failed_message\u001b[0m\u001b[0;34m)\u001b[0m\u001b[0;34m\u001b[0m\u001b[0;34m\u001b[0m\u001b[0m\n\u001b[0m\u001b[1;32m    530\u001b[0m \u001b[0;34m\u001b[0m\u001b[0m\n\u001b[1;32m    531\u001b[0m         \u001b[0;32melse\u001b[0m\u001b[0;34m:\u001b[0m\u001b[0;34m\u001b[0m\u001b[0;34m\u001b[0m\u001b[0m\n",
            "\u001b[0;31mValueError\u001b[0m: \nAll the 150 fits failed.\nIt is very likely that your model is misconfigured.\nYou can try to debug the error by setting error_score='raise'.\n\nBelow are more details about the failures:\n--------------------------------------------------------------------------------\n19 fits failed with the following error:\nTraceback (most recent call last):\n  File \"/usr/local/lib/python3.10/dist-packages/sklearn/model_selection/_validation.py\", line 888, in _fit_and_score\n    estimator.fit(X_train, y_train, **fit_params)\n  File \"/usr/local/lib/python3.10/dist-packages/sklearn/base.py\", line 1473, in wrapper\n    return fit_method(estimator, *args, **kwargs)\n  File \"/usr/local/lib/python3.10/dist-packages/sklearn/pipeline.py\", line 469, in fit\n    Xt = self._fit(X, y, routed_params)\n  File \"/usr/local/lib/python3.10/dist-packages/sklearn/pipeline.py\", line 406, in _fit\n    X, fitted_transformer = fit_transform_one_cached(\n  File \"/usr/local/lib/python3.10/dist-packages/joblib/memory.py\", line 312, in __call__\n    return self.func(*args, **kwargs)\n  File \"/usr/local/lib/python3.10/dist-packages/sklearn/pipeline.py\", line 1310, in _fit_transform_one\n    res = transformer.fit_transform(X, y, **params.get(\"fit_transform\", {}))\n  File \"/usr/local/lib/python3.10/dist-packages/sklearn/utils/_set_output.py\", line 316, in wrapped\n    data_to_wrap = f(self, X, *args, **kwargs)\n  File \"/usr/local/lib/python3.10/dist-packages/sklearn/base.py\", line 1101, in fit_transform\n    return self.fit(X, y, **fit_params).transform(X)\n  File \"/usr/local/lib/python3.10/dist-packages/sklearn/utils/_set_output.py\", line 316, in wrapped\n    data_to_wrap = f(self, X, *args, **kwargs)\n  File \"/content/drive/MyDrive/DL/codes/hatespeech/pipelines.py\", line 93, in transform\n    feature_vectors.append(np.mean(vectors, axis=0))\n  File \"/usr/local/lib/python3.10/dist-packages/numpy/core/fromnumeric.py\", line 3504, in mean\n    return _methods._mean(a, axis=axis, dtype=dtype,\n  File \"/usr/local/lib/python3.10/dist-packages/numpy/core/_methods.py\", line 102, in _mean\n    arr = asanyarray(a)\nValueError: setting an array element with a sequence. The requested array has an inhomogeneous shape after 1 dimensions. The detected shape was (9,) + inhomogeneous part.\n\n--------------------------------------------------------------------------------\n38 fits failed with the following error:\nTraceback (most recent call last):\n  File \"/usr/local/lib/python3.10/dist-packages/sklearn/model_selection/_validation.py\", line 888, in _fit_and_score\n    estimator.fit(X_train, y_train, **fit_params)\n  File \"/usr/local/lib/python3.10/dist-packages/sklearn/base.py\", line 1473, in wrapper\n    return fit_method(estimator, *args, **kwargs)\n  File \"/usr/local/lib/python3.10/dist-packages/sklearn/pipeline.py\", line 469, in fit\n    Xt = self._fit(X, y, routed_params)\n  File \"/usr/local/lib/python3.10/dist-packages/sklearn/pipeline.py\", line 406, in _fit\n    X, fitted_transformer = fit_transform_one_cached(\n  File \"/usr/local/lib/python3.10/dist-packages/joblib/memory.py\", line 312, in __call__\n    return self.func(*args, **kwargs)\n  File \"/usr/local/lib/python3.10/dist-packages/sklearn/pipeline.py\", line 1310, in _fit_transform_one\n    res = transformer.fit_transform(X, y, **params.get(\"fit_transform\", {}))\n  File \"/usr/local/lib/python3.10/dist-packages/sklearn/utils/_set_output.py\", line 316, in wrapped\n    data_to_wrap = f(self, X, *args, **kwargs)\n  File \"/usr/local/lib/python3.10/dist-packages/sklearn/base.py\", line 1101, in fit_transform\n    return self.fit(X, y, **fit_params).transform(X)\n  File \"/usr/local/lib/python3.10/dist-packages/sklearn/utils/_set_output.py\", line 316, in wrapped\n    data_to_wrap = f(self, X, *args, **kwargs)\n  File \"/content/drive/MyDrive/DL/codes/hatespeech/pipelines.py\", line 93, in transform\n    feature_vectors.append(np.mean(vectors, axis=0))\n  File \"/usr/local/lib/python3.10/dist-packages/numpy/core/fromnumeric.py\", line 3504, in mean\n    return _methods._mean(a, axis=axis, dtype=dtype,\n  File \"/usr/local/lib/python3.10/dist-packages/numpy/core/_methods.py\", line 102, in _mean\n    arr = asanyarray(a)\nValueError: setting an array element with a sequence. The requested array has an inhomogeneous shape after 1 dimensions. The detected shape was (13,) + inhomogeneous part.\n\n--------------------------------------------------------------------------------\n13 fits failed with the following error:\nTraceback (most recent call last):\n  File \"/usr/local/lib/python3.10/dist-packages/sklearn/model_selection/_validation.py\", line 888, in _fit_and_score\n    estimator.fit(X_train, y_train, **fit_params)\n  File \"/usr/local/lib/python3.10/dist-packages/sklearn/base.py\", line 1473, in wrapper\n    return fit_method(estimator, *args, **kwargs)\n  File \"/usr/local/lib/python3.10/dist-packages/sklearn/pipeline.py\", line 469, in fit\n    Xt = self._fit(X, y, routed_params)\n  File \"/usr/local/lib/python3.10/dist-packages/sklearn/pipeline.py\", line 406, in _fit\n    X, fitted_transformer = fit_transform_one_cached(\n  File \"/usr/local/lib/python3.10/dist-packages/joblib/memory.py\", line 312, in __call__\n    return self.func(*args, **kwargs)\n  File \"/usr/local/lib/python3.10/dist-packages/sklearn/pipeline.py\", line 1310, in _fit_transform_one\n    res = transformer.fit_transform(X, y, **params.get(\"fit_transform\", {}))\n  File \"/usr/local/lib/python3.10/dist-packages/sklearn/utils/_set_output.py\", line 316, in wrapped\n    data_to_wrap = f(self, X, *args, **kwargs)\n  File \"/usr/local/lib/python3.10/dist-packages/sklearn/base.py\", line 1101, in fit_transform\n    return self.fit(X, y, **fit_params).transform(X)\n  File \"/usr/local/lib/python3.10/dist-packages/sklearn/utils/_set_output.py\", line 316, in wrapped\n    data_to_wrap = f(self, X, *args, **kwargs)\n  File \"/content/drive/MyDrive/DL/codes/hatespeech/pipelines.py\", line 93, in transform\n    feature_vectors.append(np.mean(vectors, axis=0))\n  File \"/usr/local/lib/python3.10/dist-packages/numpy/core/fromnumeric.py\", line 3504, in mean\n    return _methods._mean(a, axis=axis, dtype=dtype,\n  File \"/usr/local/lib/python3.10/dist-packages/numpy/core/_methods.py\", line 102, in _mean\n    arr = asanyarray(a)\nValueError: setting an array element with a sequence. The requested array has an inhomogeneous shape after 1 dimensions. The detected shape was (8,) + inhomogeneous part.\n\n--------------------------------------------------------------------------------\n62 fits failed with the following error:\nTraceback (most recent call last):\n  File \"/usr/local/lib/python3.10/dist-packages/sklearn/model_selection/_validation.py\", line 888, in _fit_and_score\n    estimator.fit(X_train, y_train, **fit_params)\n  File \"/usr/local/lib/python3.10/dist-packages/sklearn/base.py\", line 1473, in wrapper\n    return fit_method(estimator, *args, **kwargs)\n  File \"/usr/local/lib/python3.10/dist-packages/sklearn/pipeline.py\", line 469, in fit\n    Xt = self._fit(X, y, routed_params)\n  File \"/usr/local/lib/python3.10/dist-packages/sklearn/pipeline.py\", line 406, in _fit\n    X, fitted_transformer = fit_transform_one_cached(\n  File \"/usr/local/lib/python3.10/dist-packages/joblib/memory.py\", line 312, in __call__\n    return self.func(*args, **kwargs)\n  File \"/usr/local/lib/python3.10/dist-packages/sklearn/pipeline.py\", line 1310, in _fit_transform_one\n    res = transformer.fit_transform(X, y, **params.get(\"fit_transform\", {}))\n  File \"/usr/local/lib/python3.10/dist-packages/sklearn/utils/_set_output.py\", line 316, in wrapped\n    data_to_wrap = f(self, X, *args, **kwargs)\n  File \"/usr/local/lib/python3.10/dist-packages/sklearn/base.py\", line 1101, in fit_transform\n    return self.fit(X, y, **fit_params).transform(X)\n  File \"/usr/local/lib/python3.10/dist-packages/sklearn/utils/_set_output.py\", line 316, in wrapped\n    data_to_wrap = f(self, X, *args, **kwargs)\n  File \"/content/drive/MyDrive/DL/codes/hatespeech/pipelines.py\", line 93, in transform\n    feature_vectors.append(np.mean(vectors, axis=0))\n  File \"/usr/local/lib/python3.10/dist-packages/numpy/core/fromnumeric.py\", line 3504, in mean\n    return _methods._mean(a, axis=axis, dtype=dtype,\n  File \"/usr/local/lib/python3.10/dist-packages/numpy/core/_methods.py\", line 102, in _mean\n    arr = asanyarray(a)\nValueError: setting an array element with a sequence. The requested array has an inhomogeneous shape after 1 dimensions. The detected shape was (12,) + inhomogeneous part.\n\n--------------------------------------------------------------------------------\n18 fits failed with the following error:\nTraceback (most recent call last):\n  File \"/usr/local/lib/python3.10/dist-packages/sklearn/model_selection/_validation.py\", line 888, in _fit_and_score\n    estimator.fit(X_train, y_train, **fit_params)\n  File \"/usr/local/lib/python3.10/dist-packages/sklearn/base.py\", line 1473, in wrapper\n    return fit_method(estimator, *args, **kwargs)\n  File \"/usr/local/lib/python3.10/dist-packages/sklearn/pipeline.py\", line 469, in fit\n    Xt = self._fit(X, y, routed_params)\n  File \"/usr/local/lib/python3.10/dist-packages/sklearn/pipeline.py\", line 406, in _fit\n    X, fitted_transformer = fit_transform_one_cached(\n  File \"/usr/local/lib/python3.10/dist-packages/joblib/memory.py\", line 312, in __call__\n    return self.func(*args, **kwargs)\n  File \"/usr/local/lib/python3.10/dist-packages/sklearn/pipeline.py\", line 1310, in _fit_transform_one\n    res = transformer.fit_transform(X, y, **params.get(\"fit_transform\", {}))\n  File \"/usr/local/lib/python3.10/dist-packages/sklearn/utils/_set_output.py\", line 316, in wrapped\n    data_to_wrap = f(self, X, *args, **kwargs)\n  File \"/usr/local/lib/python3.10/dist-packages/sklearn/base.py\", line 1101, in fit_transform\n    return self.fit(X, y, **fit_params).transform(X)\n  File \"/usr/local/lib/python3.10/dist-packages/sklearn/utils/_set_output.py\", line 316, in wrapped\n    data_to_wrap = f(self, X, *args, **kwargs)\n  File \"/content/drive/MyDrive/DL/codes/hatespeech/pipelines.py\", line 93, in transform\n    feature_vectors.append(np.mean(vectors, axis=0))\n  File \"/usr/local/lib/python3.10/dist-packages/numpy/core/fromnumeric.py\", line 3504, in mean\n    return _methods._mean(a, axis=axis, dtype=dtype,\n  File \"/usr/local/lib/python3.10/dist-packages/numpy/core/_methods.py\", line 102, in _mean\n    arr = asanyarray(a)\nValueError: setting an array element with a sequence. The requested array has an inhomogeneous shape after 1 dimensions. The detected shape was (7,) + inhomogeneous part.\n"
          ]
        }
      ],
      "source": [
        "ml = ML('txt',yaml_path='/content/drive/MyDrive/DL/PREG1/config.yaml')\n",
        "ml.training()\n",
        "ml.test_accuracies()"
      ]
    },
    {
      "cell_type": "code",
      "execution_count": null,
      "metadata": {
        "id": "ove1RNcwRMcv"
      },
      "outputs": [],
      "source": []
    },
    {
      "cell_type": "code",
      "execution_count": null,
      "metadata": {
        "id": "xXTt2F58RW-1"
      },
      "outputs": [],
      "source": []
    }
  ],
  "metadata": {
    "accelerator": "GPU",
    "colab": {
      "gpuType": "A100",
      "machine_shape": "hm",
      "provenance": []
    },
    "kernelspec": {
      "display_name": "Python 3",
      "name": "python3"
    },
    "language_info": {
      "codemirror_mode": {
        "name": "ipython",
        "version": 3
      },
      "file_extension": ".py",
      "mimetype": "text/x-python",
      "name": "python",
      "nbconvert_exporter": "python",
      "pygments_lexer": "ipython3",
      "version": "3.12.6"
    }
  },
  "nbformat": 4,
  "nbformat_minor": 0
}